<?xml version="1.0"?>

<robot name="SBR">

    <!-- *******************************   LINKS   *************************************** -->
    <!-- Base Link -->
    <link name="base_link">
        <inertial>
            <mass value="22.9471287282447"/>
            <origin xyz="0 0 0"/>
            <inertia ixx="10.0" ixy="0.0" ixz="0.0" iyy="10.0" iyz="0.0" izz="10.0"/>
        </inertial>

        <visual>
            <geometry>
                <mesh filename="file:///$(find sbr_pjt)/meshes/base_link.STL"/>
            </geometry>

            <origin xyz="0 0 0.4" rpy="0 0 0"/>
        </visual>

        <collision name = "base_collision">
            <geometry>
                <mesh filename="file:///$(find sbr_pjt)/meshes/base_link.STL"/>
            </geometry>

            <origin xyz="0 0 0.4" rpy="0 0 0"/>
        </collision>
    </link>

    <!-- Left Wheel -->
    <link name="left_wheel">
        <inertial>
            <mass value="3.0"/>
            <origin xyz="0 0 0"/>
            <inertia ixx="0.3" ixy="0.0" ixz="0.0" iyy="0.3" iyz="0.0" izz="0.5"/>
        </inertial>

        <visual>
            <geometry>
                <mesh filename="file:///$(find sbr_pjt)/meshes/left_wheel.STL"/>
            </geometry>

            <origin xyz="0 -0.70586 0" rpy="1.57 0 0"/>
        </visual>

        <collision>
            <geometry>
                <mesh filename="file:///$(find sbr_pjt)/meshes/left_wheel.STL"/>
            </geometry>

            <origin xyz="0 -0.70586 0" rpy="1.57 0 0"/>
        </collision>
    </link>

    <!-- Right Wheel -->
    <link name="right_wheel">
        <inertial>
            <mass value="3.0"/>
            <origin xyz="0 0 0"/>
            <inertia ixx="0.3" ixy="0.0" ixz="0.0" iyy="0.3" iyz="0.0" izz="0.5"/>
        </inertial>

        <visual>
            <geometry>
                <mesh filename="file:///$(find sbr_pjt)/meshes/right_wheel.STL"/>
            </geometry>

            <origin xyz="0 0.70586 0" rpy="1.57 0 0"/>
        </visual>

        <collision>
            <geometry>
                <mesh filename="file:///$(find sbr_pjt)/meshes/right_wheel.STL"/>
            </geometry>

            <origin xyz="0 0.70586 0" rpy="1.57 0 0"/>
        </collision>
    </link>

    <!-- Footprint -->
    <link name="base_footprint"/>

    <!-- *******************************   JOINTS   ********************************** -->
    <!-- Base to Footprint Joint  -->
    <!-- Not that important, if you're removing this then remove the footprint link as well-->
    <joint name="base_joint" type="fixed">
        <parent link="base_link"/>
        <child link="base_footprint"/>
        <origin xyz="0 0 -0.350" rpy="0 0 0"/>
    </joint>

    <!-- Left Wheel to the Base -->
    <joint name="base_left_wheel_joint" type="continuous">
        <parent link="base_link"/>
        <child link="left_wheel"/>
        <origin xyz="0 0 0" rpy="0 0 0"/>
        <axis xyz="0 1 0"/>
        <dynamics damping="3.0"/>
        <friction>4.0</friction>
    </joint>

    <!-- Right Wheel to the Base -->
    <joint name="base_right_wheel_joint" type="continuous">
        <parent link="base_link"/>
        <child link="right_wheel"/>
        <origin xyz="0 0 0" rpy="0 0 0"/>
        <axis xyz="0 1 0"/>
        <dynamics damping="3.0"/>
        <friction>4.0</friction>
    </joint>

    <!-- ****************************   IMU Sensor   **************************** -->

    <!-- IMU Link -->
    <link name="imu_link">
        <inertial>
            <mass value = "0.1"/>
            <origin value = "0 0 0"/>
            <inertia ixx="0.01" ixy="0.0" ixz="0.0" iyy="0.0" iyz="0.0" izz="0.01"/>
        </inertial>

        <visual>
            <geometry>
                <sphere radius="0.02"/>
            </geometry>
            <origin xyz="0 0 0" rpy="0 0 0"/>
        </visual>

        <collision>
            <geometry>
                <sphere radius="0.02"/>
            </geometry>
            <origin xyz="0 0 0" rpy="0 0 0"/>
        </collision>
    </link>

    <!-- IMU Joint -->
    <joint name="imu_base_link_joint" type="fixed">
        <parent link="base_link"/>
        <child link="imu_link"/>
        <origin xyz="0.01 0 0.41" rpy="0 0 0"/>
    </joint>

    <!-- IMU Ouput Definition -->
    <gazebo reference="imu_link">
        <gravity>true</gravity>
        <sensor name="imu_sensor" type="imu">
        <always_on>true</always_on>
        <update_rate>100</update_rate>
        <visualize>true</visualize>
        <plugin filename="libgazebo_ros_imu_sensor.so" name="imu">
            <bodyName>imu_link</bodyName>
            <updateRateHZ>10.0</updateRateHZ>
            <gaussianNoise>0.05</gaussianNoise>
            <xyzOffset>0 0 0</xyzOffset>
            <rpyOffset>0 0 0</rpyOffset>
            <frameName>imu_link</frameName>
            <initialOrientationAsReference>false</initialOrientationAsReference>
        </plugin>
        <pose>0 0 0 0 0 0</pose>
        </sensor>
    </gazebo>

    <!-- ***************************   Differential Drive   ***************************** -->
    <gazebo>
        <plugin name="differential_drive_controller" filename="libgazebo_ros_diff_drive.so">
            <ros>
                <!-- <namespace>/br</namespace> -->
            </ros>
            <update_rate>100.0</update_rate>

            <left_joint>base_left_wheel_joint</left_joint>
            <right_joint>base_right_wheel_joint</right_joint>
            <wheel_separation>1.17172</wheel_separation>
            <wheel_radius>0.35</wheel_radius>
            <wheel_diameter>0.7</wheel_diameter>
            <command_topic>cmd_vel</command_topic>

            <robot_base_frame>base_link</robot_base_frame>
        </plugin>
    </gazebo>

</robot>