<?xml version="1.0"?>

<robot name="SBR">

    <!-- Links -->
    <link name="base_link">
        <inertial>
            <mass value="1.0"/>
            <origin xyz="0 0 0"/>
            <inertia ixx="1.0" ixy="0.0" ixz="0.0" iyy="1.0" iyz="0.0" izz="1.0"/>
        </inertial>

        <visual>
            <geometry>
                <mesh filename="file:///$(find sbr_pjt)/meshes/base_link.STL"/>
            </geometry>

            <origin xyz="0 0 0.4" rpy="0 0 0"/>
        </visual>

        <collision>
            <geometry>
                <mesh filename="file:///$(find sbr_pjt)/meshes/base_link.STL"/>
            </geometry>

            <origin xyz="0 0 0.4" rpy="0 0 0"/>
        </collision>
    </link>

    <link name="left_wheel">
        <inertial>
            <mass value="1.0"/>
            <origin xyz="0 0 0"/>
            <inertia ixx="1.0" ixy="0.0" ixz="0.0" iyy="1.0" iyz="0.0" izz="1.0"/>
        </inertial>

        <visual>
            <geometry>
                <mesh filename="file:///$(find sbr_pjt)/meshes/left_wheel.STL"/>
            </geometry>

            <origin xyz="0 -0.70586 0" rpy="1.57 0 0"/>
        </visual>

        <collision>
            <geometry>
                <mesh filename="file:///$(find sbr_pjt)/meshes/left_wheel.STL"/>
            </geometry>

            <origin xyz="0 -0.70586 0" rpy="1.57 0 0"/>
        </collision>
    </link>

    <link name="right_wheel">
        <inertial>
            <mass value="1.0"/>
            <origin xyz="0 0 0"/>
            <inertia ixx="1.0" ixy="0.0" ixz="0.0" iyy="1.0" iyz="0.0" izz="1.0"/>
        </inertial>

        <visual>
            <geometry>
                <mesh filename="file:///$(find sbr_pjt)/meshes/right_wheel.STL"/>
            </geometry>

            <origin xyz="0 0.70586 0" rpy="1.57 0 0"/>
        </visual>

        <collision>
            <geometry>
                <mesh filename="file:///$(find sbr_pjt)/meshes/right_wheel.STL"/>
            </geometry>

            <origin xyz="0 0.70586 0" rpy="1.57 0 0"/>
        </collision>
    </link>

    <link name="base_footprint"/>


    <!-- Joints -->
    <joint name="base_joint" type="fixed">
        <parent link="base_link"/>
        <child link="base_footprint"/>
        <origin xyz="0 0 -0.350" rpy="0 0 0"/>
    </joint>

    <joint name="base_left_wheel_joint" type="continuous">
        <parent link="base_link"/>
        <child link="left_wheel"/>
        <origin xyz="0 0 0" rpy="0 0 0"/>
        <axis xyz="0 1 0"/>
    </joint>

    <joint name="base_right_wheel_joint" type="continuous">
        <parent link="base_link"/>
        <child link="right_wheel"/>
        <origin xyz="0 0 0" rpy="0 0 0"/>
        <axis xyz="0 1 0"/>
    </joint>

</robot>